[ERROR] 2018-07-06 02:02:23,539 | /home/frappe/frappe-bench/apps/frappe/frappe/utils/error.py:
Could not take error snapshot: 'connection'
Traceback (most recent call last):
  File "/home/frappe/frappe-bench/apps/frappe/frappe/utils/error.py", line 36, in make_error_snapshot
    snapshot = get_snapshot(exception)
  File "/home/frappe/frappe-bench/apps/frappe/frappe/utils/error.py", line 81, in get_snapshot
    call = inspect.formatargvalues(args, varargs, varkw, locals, formatvalue=lambda value: '={}'.format(pydoc.text.repr(value)))
  File "/usr/lib/python2.7/inspect.py", line 888, in formatargvalues
    specs.append(strseq(args[i], convert, join))
  File "/usr/lib/python2.7/inspect.py", line 843, in strseq
    return convert(object)
  File "/usr/lib/python2.7/inspect.py", line 885, in convert
    return formatarg(name) + formatvalue(locals[name])
KeyError: 'connection'
