[ERROR] 2018-07-18 02:03:58,339 | /home/frappe/frappe-bench/apps/frappe/frappe/utils/error.py:
Could not take error snapshot: 'connection'
Traceback (most recent call last):
  File "/home/frappe/frappe-bench/apps/frappe/frappe/utils/error.py", line 36, in make_error_snapshot
    snapshot = get_snapshot(exception)
  File "/home/frappe/frappe-bench/apps/frappe/frappe/utils/error.py", line 81, in get_snapshot
    call = inspect.formatargvalues(args, varargs, varkw, locals, formatvalue=lambda value: '={}'.format(pydoc.text.repr(value)))
  File "/usr/lib/python2.7/inspect.py", line 888, in formatargvalues
    specs.append(strseq(args[i], convert, join))
  File "/usr/lib/python2.7/inspect.py", line 843, in strseq
    return convert(object)
  File "/usr/lib/python2.7/inspect.py", line 885, in convert
    return formatarg(name) + formatvalue(locals[name])
KeyError: 'connection'
[ERROR] 2018-07-18 02:03:58,406 | /home/frappe/frappe-bench/apps/frappe/frappe/utils/error.py:
Could not take error snapshot: 'connection'
Traceback (most recent call last):
  File "/home/frappe/frappe-bench/apps/frappe/frappe/utils/error.py", line 36, in make_error_snapshot
    snapshot = get_snapshot(exception)
  File "/home/frappe/frappe-bench/apps/frappe/frappe/utils/error.py", line 81, in get_snapshot
    call = inspect.formatargvalues(args, varargs, varkw, locals, formatvalue=lambda value: '={}'.format(pydoc.text.repr(value)))
  File "/usr/lib/python2.7/inspect.py", line 888, in formatargvalues
    specs.append(strseq(args[i], convert, join))
  File "/usr/lib/python2.7/inspect.py", line 843, in strseq
    return convert(object)
  File "/usr/lib/python2.7/inspect.py", line 885, in convert
    return formatarg(name) + formatvalue(locals[name])
KeyError: 'connection'
[ERROR] 2018-07-18 02:03:58,417 | /home/frappe/frappe-bench/apps/frappe/frappe/utils/error.py:
Could not take error snapshot: 'connection'
Traceback (most recent call last):
  File "/home/frappe/frappe-bench/apps/frappe/frappe/utils/error.py", line 36, in make_error_snapshot
    snapshot = get_snapshot(exception)
  File "/home/frappe/frappe-bench/apps/frappe/frappe/utils/error.py", line 81, in get_snapshot
    call = inspect.formatargvalues(args, varargs, varkw, locals, formatvalue=lambda value: '={}'.format(pydoc.text.repr(value)))
  File "/usr/lib/python2.7/inspect.py", line 888, in formatargvalues
    specs.append(strseq(args[i], convert, join))
  File "/usr/lib/python2.7/inspect.py", line 843, in strseq
    return convert(object)
  File "/usr/lib/python2.7/inspect.py", line 885, in convert
    return formatarg(name) + formatvalue(locals[name])
KeyError: 'connection'
[ERROR] 2018-07-18 02:03:58,428 | /home/frappe/frappe-bench/apps/frappe/frappe/utils/error.py:
Could not take error snapshot: 'connection'
Traceback (most recent call last):
  File "/home/frappe/frappe-bench/apps/frappe/frappe/utils/error.py", line 36, in make_error_snapshot
    snapshot = get_snapshot(exception)
  File "/home/frappe/frappe-bench/apps/frappe/frappe/utils/error.py", line 81, in get_snapshot
    call = inspect.formatargvalues(args, varargs, varkw, locals, formatvalue=lambda value: '={}'.format(pydoc.text.repr(value)))
  File "/usr/lib/python2.7/inspect.py", line 888, in formatargvalues
    specs.append(strseq(args[i], convert, join))
  File "/usr/lib/python2.7/inspect.py", line 843, in strseq
    return convert(object)
  File "/usr/lib/python2.7/inspect.py", line 885, in convert
    return formatarg(name) + formatvalue(locals[name])
KeyError: 'connection'
[ERROR] 2018-07-18 02:03:58,441 | /home/frappe/frappe-bench/apps/frappe/frappe/utils/error.py:
Could not take error snapshot: 'connection'
Traceback (most recent call last):
  File "/home/frappe/frappe-bench/apps/frappe/frappe/utils/error.py", line 36, in make_error_snapshot
    snapshot = get_snapshot(exception)
  File "/home/frappe/frappe-bench/apps/frappe/frappe/utils/error.py", line 81, in get_snapshot
    call = inspect.formatargvalues(args, varargs, varkw, locals, formatvalue=lambda value: '={}'.format(pydoc.text.repr(value)))
  File "/usr/lib/python2.7/inspect.py", line 888, in formatargvalues
    specs.append(strseq(args[i], convert, join))
  File "/usr/lib/python2.7/inspect.py", line 843, in strseq
    return convert(object)
  File "/usr/lib/python2.7/inspect.py", line 885, in convert
    return formatarg(name) + formatvalue(locals[name])
KeyError: 'connection'
[ERROR] 2018-07-18 02:03:58,452 | /home/frappe/frappe-bench/apps/frappe/frappe/utils/error.py:
Could not take error snapshot: 'connection'
Traceback (most recent call last):
  File "/home/frappe/frappe-bench/apps/frappe/frappe/utils/error.py", line 36, in make_error_snapshot
    snapshot = get_snapshot(exception)
  File "/home/frappe/frappe-bench/apps/frappe/frappe/utils/error.py", line 81, in get_snapshot
    call = inspect.formatargvalues(args, varargs, varkw, locals, formatvalue=lambda value: '={}'.format(pydoc.text.repr(value)))
  File "/usr/lib/python2.7/inspect.py", line 888, in formatargvalues
    specs.append(strseq(args[i], convert, join))
  File "/usr/lib/python2.7/inspect.py", line 843, in strseq
    return convert(object)
  File "/usr/lib/python2.7/inspect.py", line 885, in convert
    return formatarg(name) + formatvalue(locals[name])
KeyError: 'connection'
[ERROR] 2018-07-18 02:03:58,463 | /home/frappe/frappe-bench/apps/frappe/frappe/utils/error.py:
Could not take error snapshot: 'connection'
Traceback (most recent call last):
  File "/home/frappe/frappe-bench/apps/frappe/frappe/utils/error.py", line 36, in make_error_snapshot
    snapshot = get_snapshot(exception)
  File "/home/frappe/frappe-bench/apps/frappe/frappe/utils/error.py", line 81, in get_snapshot
    call = inspect.formatargvalues(args, varargs, varkw, locals, formatvalue=lambda value: '={}'.format(pydoc.text.repr(value)))
  File "/usr/lib/python2.7/inspect.py", line 888, in formatargvalues
    specs.append(strseq(args[i], convert, join))
  File "/usr/lib/python2.7/inspect.py", line 843, in strseq
    return convert(object)
  File "/usr/lib/python2.7/inspect.py", line 885, in convert
    return formatarg(name) + formatvalue(locals[name])
KeyError: 'connection'
[ERROR] 2018-07-18 11:31:26,864 | /home/frappe/frappe-bench/apps/frappe/frappe/utils/error.py:
New Exception collected with id: 2018-07-18 11:31:26.825356-10.0.2.2-5d3
